<?xml version="1.0" ?>
<robot name="rosbot" xmlns:xacro="http://www.ros.org/wiki/xacro">

<xacro:include filename="$(find rosbot_description)/urdf/materials.xacro" />
<xacro:include filename="$(find rosbot_description)/urdf/rosbot.trans" />
<xacro:include filename="$(find rosbot_description)/urdf/rosbot.gazebo" />
<link name="base_link">
  <inertial>
    <origin xyz="-3.749576081263265e-14 -1.474920661336075e-16 0.09200116316942011" rpy="0 0 0"/>
    <mass value="2.3530972702094903"/>
    <inertia ixx="0.027245" iyy="0.027245" izz="0.026163" ixy="0.0" iyz="-0.0" ixz="0.0"/>
  </inertial>
  <visual>
    <origin xyz="0 0 0" rpy="0 0 0"/>
    <geometry>
      <mesh filename="file://$(find rosbot_description)/meshes/base_link.stl" scale="0.001 0.001 0.001"/>
    </geometry>
    <material name="silver"/>
  </visual>
  <collision>
    <origin xyz="0 0 0" rpy="0 0 0"/>
    <geometry>
      <mesh filename="file://$(find rosbot_description)/meshes/base_link.stl" scale="0.001 0.001 0.001"/>
    </geometry>
  </collision>
</link>

<link name="lb_wheel_1">
  <inertial>
    <origin xyz="0.005413780765341936 -0.005382734458352467 -2.551672796897303e-05" rpy="0 0 0"/>
    <mass value="0.0778319216075838"/>
    <inertia ixx="8.3e-05" iyy="8.3e-05" izz="5.7e-05" ixy="-2.5e-05" iyz="0.0" ixz="0.0"/>
  </inertial>
  <visual>
    <origin xyz="0.132071 -0.132071 -0.04845" rpy="0 0 0"/>
    <geometry>
      <mesh filename="file://$(find rosbot_description)/meshes/lb_wheel_1.stl" scale="0.001 0.001 0.001"/>
    </geometry>
    <material name="silver"/>
  </visual>
  <collision>
    <origin xyz="0.132071 -0.132071 -0.04845" rpy="0 0 0"/>
    <geometry>
      <mesh filename="file://$(find rosbot_description)/meshes/lb_wheel_1.stl" scale="0.001 0.001 0.001"/>
    </geometry>
  </collision>
</link>

<link name="lw_wheel_1">
  <inertial>
    <origin xyz="-0.005413780765340992 -0.0053827344583514125 2.5516727968480368e-05" rpy="0 0 0"/>
    <mass value="0.07783192160758527"/>
    <inertia ixx="8.3e-05" iyy="8.3e-05" izz="5.7e-05" ixy="2.5e-05" iyz="-0.0" ixz="0.0"/>
  </inertial>
  <visual>
    <origin xyz="-0.132071 -0.132071 -0.04845" rpy="0 0 0"/>
    <geometry>
      <mesh filename="file://$(find rosbot_description)/meshes/lw_wheel_1.stl" scale="0.001 0.001 0.001"/>
    </geometry>
    <material name="silver"/>
  </visual>
  <collision>
    <origin xyz="-0.132071 -0.132071 -0.04845" rpy="0 0 0"/>
    <geometry>
      <mesh filename="file://$(find rosbot_description)/meshes/lw_wheel_1.stl" scale="0.001 0.001 0.001"/>
    </geometry>
  </collision>
</link>

<link name="rw_wheel_1">
  <inertial>
    <origin xyz="-0.005416332872606844 0.00538019146711749 2.191107892976496e-05" rpy="0 0 0"/>
    <mass value="0.07783193873752603"/>
    <inertia ixx="8.3e-05" iyy="8.3e-05" izz="5.8e-05" ixy="-2.5e-05" iyz="0.0" ixz="0.0"/>
  </inertial>
  <visual>
    <origin xyz="-0.132071 0.132071 -0.04845" rpy="0 0 0"/>
    <geometry>
      <mesh filename="file://$(find rosbot_description)/meshes/rw_wheel_1.stl" scale="0.001 0.001 0.001"/>
    </geometry>
    <material name="silver"/>
  </visual>
  <collision>
    <origin xyz="-0.132071 0.132071 -0.04845" rpy="0 0 0"/>
    <geometry>
      <mesh filename="file://$(find rosbot_description)/meshes/rw_wheel_1.stl" scale="0.001 0.001 0.001"/>
    </geometry>
  </collision>
</link>

<link name="rb_wheel_1">
  <inertial>
    <origin xyz="0.00539067515626529 0.0054217214632542865 2.5516727968813435e-05" rpy="0 0 0"/>
    <mass value="0.07783192160758773"/>
    <inertia ixx="8.3e-05" iyy="8.3e-05" izz="5.7e-05" ixy="2.5e-05" iyz="-0.0" ixz="0.0"/>
  </inertial>
  <visual>
    <origin xyz="0.132071 0.132071 -0.04845" rpy="0 0 0"/>
    <geometry>
      <mesh filename="file://$(find rosbot_description)/meshes/rb_wheel_1.stl" scale="0.001 0.001 0.001"/>
    </geometry>
    <material name="silver"/>
  </visual>
  <collision>
    <origin xyz="0.132071 0.132071 -0.04845" rpy="0 0 0"/>
    <geometry>
      <mesh filename="file://$(find rosbot_description)/meshes/rb_wheel_1.stl" scale="0.001 0.001 0.001"/>
    </geometry>
  </collision>
</link>

<link name="rp_lidar_1">
  <inertial>
    <origin xyz="0.008987901819230128 -0.00054985044767053 0.016419272899719672" rpy="0 0 0"/>
    <mass value="0.07378209902759401"/>
    <inertia ixx="3.1e-05" iyy="6.1e-05" izz="7.2e-05" ixy="-1e-06" iyz="0.0" ixz="6e-06"/>
  </inertial>
  <visual>
    <origin xyz="-0.0 -0.0 -0.23445" rpy="0 0 0"/>
    <geometry>
      <mesh filename="file://$(find rosbot_description)/meshes/rp_lidar_1.stl" scale="0.001 0.001 0.001"/>
    </geometry>
    <material name="silver"/>
  </visual>
  <collision>
    <origin xyz="-0.0 -0.0 -0.23445" rpy="0 0 0"/>
    <geometry>
      <mesh filename="file://$(find rosbot_description)/meshes/rp_lidar_1.stl" scale="0.001 0.001 0.001"/>
    </geometry>
  </collision>
</link>

<joint name="lb_joint" type="continuous">
  <origin xyz="-0.132071 0.132071 0.04845" rpy="0 0 0"/>
  <parent link="base_link"/>
  <child link="lb_wheel_1"/>
  <axis xyz="-0.707107 0.707107 -0.0"/>
</joint>

<joint name="lw_joint" type="continuous">
  <origin xyz="0.132071 0.132071 0.04845" rpy="0 0 0"/>
  <parent link="base_link"/>
  <child link="lw_wheel_1"/>
  <axis xyz="0.707107 0.707107 0.0"/>
</joint>

<joint name="rw_joint" type="continuous">
  <origin xyz="0.132071 -0.132071 0.04845" rpy="0 0 0"/>
  <parent link="base_link"/>
  <child link="rw_wheel_1"/>
  <axis xyz="0.707107 -0.707107 0.0"/>
</joint>

<joint name="rb_joint" type="continuous">
  <origin xyz="-0.132071 -0.132071 0.04845" rpy="0 0 0"/>
  <parent link="base_link"/>
  <child link="rb_wheel_1"/>
  <axis xyz="-0.707107 -0.707107 -0.0"/>
</joint>

<joint name="rp_joint" type="fixed">
  <origin xyz="0.0 0.0 0.23445" rpy="0 0 0"/>
  <parent link="base_link"/>
  <child link="rp_lidar_1"/>
</joint>

</robot>
